#VRML_SIM R2020b utf8
WorldInfo {
  coordinateSystem "NUE"
}
Viewpoint {
  orientation 0.03812842342819167 0.980685634309985 -0.19183823911020145 0.3711676765842955
  position 1.0018674752272085 0.5645975460512958 2.304176345257513
}
TexturedBackground {
}
TexturedBackgroundLight {
}
RectangleArena {
  translation 0.05 0 0
}
Robot {
  children [
    Solid {
      children [
        HingeJoint {
          jointParameters HingeJointParameters {
            axis 0 1 0
            minStop -2.8973
            maxStop 2.8973
          }
          endPoint Solid {
            translation 0 0.333 0
            children [
              HingeJoint {
                jointParameters HingeJointParameters {
                  axis 0 0 1
                  minStop -1.7628
                  maxStop 1.7628
                }
                endPoint Solid {
                  rotation -1 0 0 1.5707996938995745
                  children [
                    HingeJoint {
                      jointParameters HingeJointParameters {
                        axis 0 0 1
                        minStop -2.8973
                        maxStop 2.8973
                      }
                      endPoint Solid {
                        translation 0 0 0.316
                        rotation 1 0 0 1.5707996938995745
                        children [
                          HingeJoint {
                            jointParameters HingeJointParameters {
                              position -0.07
                              axis 0 0 1
                              anchor 0.0825 0 0
                              minStop -3.0718
                              maxStop -0.0698
                            }
                            endPoint Solid {
                              translation 0.0825 0 0
                              rotation 0.9987762530223677 -0.03497145003088227 -0.03497133227854752 1.5720241899584464
                              children [
                                HingeJoint {
                                  jointParameters HingeJointParameters {
                                    axis 0 0 1
                                    anchor -0.0825 0 0
                                    minStop -2.8973
                                    maxStop 2.8973
                                  }
                                  endPoint Solid {
                                    translation -0.0825 0 -0.384
                                    rotation -1 0 0 1.5707996938995745
                                    children [
                                      HingeJoint {
                                        jointParameters HingeJointParameters {
                                          axis 0 0 1
                                          minStop -0.0175
                                          maxStop 3.7525
                                        }
                                        endPoint Solid {
                                          rotation 1 0 0 1.5708003061004252
                                          children [
                                            HingeJoint {
                                              jointParameters HingeJointParameters {
                                                axis 0 0 1
                                                anchor 0.088 0 0
                                                minStop -2.8973
                                                maxStop 2.8973
                                              }
                                              endPoint Solid {
                                                translation 0.088 0 0.107
                                                rotation -1 0 0 1.5708003061004252
                                                children [
                                                  HingeJoint {
                                                    jointParameters HingeJointParameters {
                                                      axis 0 1 0
                                                    }
                                                    endPoint Solid {
                                                      children [
                                                        SliderJoint {
                                                          jointParameters JointParameters {
                                                            position 0.03
                                                            axis 0 0 -1
                                                          }
                                                          endPoint Solid {
                                                            translation 0 0 -0.03
                                                            rotation 0 0 1 3.141592653589793
                                                            children [
                                                              DEF RightFinger Shape {
                                                                appearance PBRAppearance {
                                                                  baseColor 0.3 0.3 0.3
                                                                  metalness 0
                                                                }
                                                                geometry Mesh {
                                                                  url [
                                                                    "/media/ddelehel/932ed56b-ad6e-4d5b-aa8e-f6fdada03cb1/ddelehel/catkin_ws/src/franka_ros/franka_description/meshes/visual/finger.dae"
                                                                  ]
                                                                }
                                                              }
                                                            ]
                                                            name "RightFinger"
                                                            boundingObject USE RightFinger
                                                            physics Physics {
                                                              mass 0.68
                                                              centerOfMass [
                                                                0 0 0
                                                              ]
                                                              inertiaMatrix [
                                                                1 1 1
                                                                0.1 0.1 0.1
                                                              ]
                                                            }
                                                          }
                                                        }
                                                        SliderJoint {
                                                          jointParameters JointParameters {
                                                            position 0.03
                                                          }
                                                          endPoint Solid {
                                                            translation 0 0 0.03
                                                            rotation 1 0 0 3.141592653589793
                                                            children [
                                                              DEF LeftFinger Shape {
                                                                appearance PBRAppearance {
                                                                  baseColor 0.3 0.3 0.3
                                                                  metalness 0
                                                                }
                                                                geometry Mesh {
                                                                  url [
                                                                    "/media/ddelehel/932ed56b-ad6e-4d5b-aa8e-f6fdada03cb1/ddelehel/catkin_ws/src/franka_ros/franka_description/meshes/visual/finger.dae"
                                                                  ]
                                                                }
                                                              }
                                                            ]
                                                            name "LeftFinger"
                                                            boundingObject USE LeftFinger
                                                            physics Physics {
                                                              mass 0.68
                                                              centerOfMass [
                                                                0 0 0
                                                              ]
                                                              inertiaMatrix [
                                                                1 1 1
                                                                0.1 0.1 0.1
                                                              ]
                                                            }
                                                          }
                                                        }
                                                        DEF Hand Shape {
                                                          appearance PBRAppearance {
                                                            baseColor 0.5 0.5 0.5
                                                            metalness 0
                                                          }
                                                          geometry Mesh {
                                                            url [
                                                              "/media/ddelehel/932ed56b-ad6e-4d5b-aa8e-f6fdada03cb1/ddelehel/catkin_ws/src/franka_ros/franka_description/meshes/visual/hand.dae"
                                                            ]
                                                          }
                                                        }
                                                      ]
                                                      name "hand"
                                                      boundingObject USE Hand
                                                      physics Physics {
                                                      }
                                                    }
                                                  }
                                                  DEF Link7 Shape {
                                                    appearance PBRAppearance {
                                                      metalness 0
                                                    }
                                                    geometry Mesh {
                                                      url [
                                                        "/media/ddelehel/932ed56b-ad6e-4d5b-aa8e-f6fdada03cb1/ddelehel/catkin_ws/src/franka_ros/franka_description/meshes/visual/link7.dae"
                                                      ]
                                                    }
                                                  }
                                                ]
                                                name "link7"
                                                boundingObject USE Link7
                                                physics Physics {
                                                  mass 1.58
                                                  centerOfMass [
                                                    0 0 0
                                                  ]
                                                  inertiaMatrix [
                                                    1 1 1
                                                    0.7 0.7 0.7
                                                  ]
                                                }
                                              }
                                            }
                                            DEF Link6 Shape {
                                              appearance PBRAppearance {
                                                metalness 0
                                              }
                                              geometry Mesh {
                                                url [
                                                  "/media/ddelehel/932ed56b-ad6e-4d5b-aa8e-f6fdada03cb1/ddelehel/catkin_ws/src/franka_ros/franka_description/meshes/visual/link6.dae"
                                                ]
                                              }
                                            }
                                          ]
                                          name "link6"
                                          boundingObject USE Link6
                                          physics Physics {
                                            mass 1.47
                                            centerOfMass [
                                              0 0 0
                                            ]
                                            inertiaMatrix [
                                              1 1 1
                                              0.3 0.3 0.3
                                            ]
                                          }
                                        }
                                      }
                                      DEF Link5 Shape {
                                        appearance PBRAppearance {
                                          metalness 0
                                        }
                                        geometry Mesh {
                                          url [
                                            "/media/ddelehel/932ed56b-ad6e-4d5b-aa8e-f6fdada03cb1/ddelehel/catkin_ws/src/franka_ros/franka_description/meshes/visual/link5.dae"
                                          ]
                                        }
                                      }
                                    ]
                                    name "link5"
                                    boundingObject USE Link5
                                    physics Physics {
                                      mass 3.5
                                      centerOfMass [
                                        0 0 0
                                      ]
                                      inertiaMatrix [
                                        1 1 1
                                        0.3 0.3 0.3
                                      ]
                                    }
                                  }
                                }
                                DEF Link4 Shape {
                                  appearance PBRAppearance {
                                    metalness 0
                                  }
                                  geometry Mesh {
                                    url [
                                      "/media/ddelehel/932ed56b-ad6e-4d5b-aa8e-f6fdada03cb1/ddelehel/catkin_ws/src/franka_ros/franka_description/meshes/visual/link4.dae"
                                    ]
                                  }
                                }
                              ]
                              name "link4"
                              boundingObject USE Link4
                              physics Physics {
                                mass 2.43
                                centerOfMass [
                                  0 0 0
                                ]
                                inertiaMatrix [
                                  1 1 1
                                  0.3 0.3 0.3
                                ]
                              }
                            }
                          }
                          DEF Link3 Shape {
                            appearance PBRAppearance {
                              metalness 0
                            }
                            geometry Mesh {
                              url [
                                "/media/ddelehel/932ed56b-ad6e-4d5b-aa8e-f6fdada03cb1/ddelehel/catkin_ws/src/franka_ros/franka_description/meshes/visual/link3.dae"
                              ]
                            }
                          }
                        ]
                        name "link3"
                        boundingObject USE Link3
                        physics Physics {
                          mass 2.38
                          centerOfMass [
                            0 0 0
                          ]
                          inertiaMatrix [
                            1 1 1
                            0.3 0.3 0.3
                          ]
                        }
                      }
                    }
                    DEF Link2 Shape {
                      appearance PBRAppearance {
                        metalness 0
                      }
                      geometry Mesh {
                        url [
                          "/media/ddelehel/932ed56b-ad6e-4d5b-aa8e-f6fdada03cb1/ddelehel/catkin_ws/src/franka_ros/franka_description/meshes/visual/link2.dae"
                        ]
                      }
                    }
                  ]
                  name "link2"
                  boundingObject USE Link2
                  physics Physics {
                    mass 2.36
                    centerOfMass [
                      0 0 0
                    ]
                    inertiaMatrix [
                      1 1 1
                      0.3 0.3 0.3
                    ]
                  }
                }
              }
              DEF Link1 Shape {
                appearance PBRAppearance {
                  metalness 0
                }
                geometry Mesh {
                  url [
                    "/media/ddelehel/932ed56b-ad6e-4d5b-aa8e-f6fdada03cb1/ddelehel/catkin_ws/src/franka_ros/franka_description/meshes/visual/link1.dae"
                  ]
                }
              }
            ]
            name "link1"
            boundingObject USE Link1
            physics Physics {
              mass 2.34
              centerOfMass [
                0 0 0
              ]
              inertiaMatrix [
                1 1 1
                0.3 0.3 0.3
              ]
            }
          }
        }
        DEF Link0 Shape {
          appearance PBRAppearance {
            metalness 0
          }
          geometry Mesh {
            url [
              "/media/ddelehel/932ed56b-ad6e-4d5b-aa8e-f6fdada03cb1/ddelehel/catkin_ws/src/franka_ros/franka_description/meshes/visual/link0.dae"
            ]
          }
        }
      ]
      name "link0"
      boundingObject USE Link0
      physics Physics {
        mass 3.06
        centerOfMass [
          0 0 0
        ]
        inertiaMatrix [
          1 1 1
          0.3 0.3 0.3
        ]
      }
    }
  ]
}
